<?xml version="1.0"?>
<robot name="my_gpg">

  <ros2_control name="gpg_remote" type="system">
    <hardware>
      <plugin>gpg_remote/GPGRemoteHardware</plugin>
      <param name="host">192.168.0.204</param>
      <param name="port">8002</param>
    </hardware>
    
    <joint name="left_wheel">
      <command_interface name="velocity"/>
      <state_interface name="position"/>
      <state_interface name="velocity"/>  
    </joint>
    <joint name="right_wheel">
      <command_interface name="velocity"/>
      <state_interface name="position"/>
      <state_interface name="velocity"/>  
    </joint>
    <joint name="servo">
      <command_interface name="position"/>
      <state_interface name="position"/>
    </joint>
    <sensor name="line">
       <state_interface name="level0"/>
       <state_interface name="level1"/>
       <state_interface name="level2"/>
       <state_interface name="level3"/>
       <state_interface name="level4"/>
    </sensor>
    <sensor name="battery">
       <state_interface name="voltage"/>
    </sensor>
  </ros2_control>

    <link name="base_link">
        <visual>
            <geometry>
                <box size="0.15 0.15 0.075"/>
            </geometry>
        </visual>
    </link>
    <link name="servo_link">
        <visual>
            <geometry>
                <box size="0.05 0.05 0.05"/>
            </geometry>
            <origin xyz="0.0 0.0 0.0"/>
        </visual>
    </link>
    <link name="left_wheel_link">
        <visual>
            <geometry>
                <cylinder radius="0.065" length="0.025"/>
            </geometry>
            <origin xyz="0 0.0 0.0" rpy="1.57075 0 0"/>
        </visual>
    </link>
    <link name="right_wheel_link">
        <visual>
            <geometry>
                <cylinder radius="0.065" length="0.025"/>
                
            </geometry>
            <origin xyz="0 0.0 0.0" rpy="1.57075 0 0"/>
        </visual>
    </link>
    <joint name="left_wheel" type="continuous">
        
        <parent link="base_link"/>
        <child link="left_wheel_link"/>
        <origin rpy="0 0 0" xyz="0.0 0.10 -0.03"/>
        <axis xyz="0 1 0"/>
        
    </joint>
    <joint name="right_wheel" type="continuous">
        <parent link="base_link"/>
        <child link="right_wheel_link"/>
        <origin xyz="0 -0.10 -0.03"/>
        <axis xyz="0 1 0"/>
        
    </joint>

    <joint name="servo" type="revolute">
        <limit effort="1000.0" lower="0.0" upper="0.548" velocity="0.5"/>
        <parent link="base_link"/>
        <origin xyz="0.10 0  0.03"/>
        <child link="servo_link"/>
        <axis xyz="0 0 1"/>
        
    </joint>
</robot>